Workbook

Sheet Draft Picks 2015-2025
A1: Player-Pick Model
A2: Year | B2: Pick | C2: Team | D2: Player | E2: College/Country | F2: Career Outcome Tier
A3: 2015 | B3: 1 | C3: Minnesota Timberwolves | D3: Karl-Anthony Towns | E3: Kentucky | F3: 🟩 Superstar
A4: 2016 | B4: 1 | C4: Philadelphia 76ers | D4: Ben Simmons | E4: LSU | F4: 🟦 Star / All-Star
A5: 2017 | B5: 1 | C5: Philadelphia 76ers | D5: Markelle Fultz | E5: Washington | F5: 🟥 Bust
A6: 2018 | B6: 1 | C6: Phoenix Suns | D6: Deandre Ayton | E6: Arizona | F6: 🟨 Above-average starter
A7: 2019 | B7: 1 | C7: New Orleans Pelicans | D7: Zion Williamson | E7: Duke | F7: 🟦 Star / All-Star
A8: 2020 | B8: 1 | C8: Minnesota Timberwolves | D8: Anthony Edwards | E8: Georgia | F8: 🟩 Superstar
A9: 2021 | B9: 1 | C9: Detroit Pistons | D9: Cade Cunningham | E9: Oklahoma State | F9: 🟩 Superstar
A10: 2022 | B10: 1 | C10: Orlando Magic | D10: Paolo Banchero | E10: Duke | F10: 🟦 Star / All-Star
A11: 2023 | B11: 1 | C11: San Antonio Spurs | D11: Victor Wembanyama | E11: France | F11: 🟩 Superstar
A12: 2024 | B12: 1 | C12: Atlanta Hawks | D12: Zaccharie Risacher | E12: France | F12: ⏳ Too early to tell
A13: 2025 | B13: 1 | C13: Dallas Mavericks | D13: Cooper Flagg | E13: Duke | F13: ⏳ Too early to tell
A14: 2015 | B14: 2 | C14: LA Lakers | D14: D'Angelo Russell | E14: Ohio State | F14: 🟦 Star / All-Star
... A332: 2025 | B332: 30 | C332: LA Clippers | D332: Yanic Konan Niederhauser | E332: Penn State | F332: ⏳ Too early to tell

Sheet Legend
A1: Emoji | B1: Tier | C1: Meaning
A2: 🟩 | B2: Superstar | C2: MVP-caliber / perennial All-NBA, top tier of the league
A3: 🟦 | B3: Star / All-Star | C3: At least one All-Star selection or clear All-Star-level production
A4: 🟨 | B4: Above-average starter | C4: Long-time quality starter, not an All-Star
A5: ⬛ | B5: Contributor / role player | C5: Rotation/bench piece, solid NBA role
A6: 🟥 | B6: Bust | C6: Did not pan out relative to draft slot; replacement level or out of the league
A7: ⏳ | B7: Too early to tell | C7: 2024-2025 picks; not enough career sample yet to judge
A9: Note: Tiers are a subjective judgment call based on All-Star/All-NBA selections, career advanced stats (Win Shares, BPM, VORP via Basketball-Reference), and games played through the 2025-26 season. 2024 and 2025 draft classes are marked 'Too early to tell' given limited career sample size.

Sheet Stat Analysis
A1: Player-Pick Model | I1: First Round Statistics | K1: Picks 1-5 | M1: Picks 6-10 | O1: Picks 11-15 | Q1: Picks 16-20 | S1: Picks 21-25 | U1: Picks 26-30
A2: Year | B2: Pick | C2: Team | D2: Player | E2: College/Country | F2: Career Outcome Tier | G2: Score Indicator
A3: 2015 | B3: 1 | C3: Minnesota Timberwolves | D3: Karl-Anthony Towns | E3: Kentucky | F3: 🟩 Superstar | G3: {=_xlfn.SWITCH(F3,"🟩 Superstar",5,"🟦 Star / All-Star",4,"🟨 Above-average starter",3,"⬛ Contributor / role player",2,"🟥 Bust",1,"⏳ Too early to tell","")} -> 5 | I3: n | J3: =COUNT(G3:G332) -> 274 | K3: n | L3: =COUNT(G3:G57) -> 45 | M3: n | N3: =COUNT(G58:G112) -> 45 | O3: n | P3: =COUNT(G113:G167) -> 45 | Q3: n | R3: =COUNT(G168:G222) -> 47 | S3: n | T3: =COUNT(G223:G277) -> 46 | U3: n | V3: =COUNT(G278:G332) -> 46
A4: 2016 | B4: 1 | C4: Philadelphia 76ers | D4: Ben Simmons | E4: LSU | F4: 🟦 Star / All-Star | G4: {=_xlfn.SWITCH(F4,"🟩 Superstar",5,"🟦 Star / All-Star",4,"🟨 Above-average starter",3,"⬛ Contributor / role player",2,"🟥 Bust",1,"⏳ Too early to tell","")} -> 4 | I4: mean | J4: {=AVERAGE(IF(ISNUMBER(G3:G332),G3:G332))} -> 2.2518248 | K4: mean | L4: {=AVERAGE(IF(ISNUMBER(G3:G57),G3:G57))} -> 3.2444444 | M4: mean | N4: {=AVERAGE(IF(ISNUMBER(G58:G112),G58:G112))} -> 2.2 | O4: mean | P4: {=AVERAGE(IF(ISNUMBER(G113:G167),G113:G167))} -> 2.3777778 | Q4: mean | R4: {=AVERAGE(IF(ISNUMBER(G168:G222),G168:G222))} -> 1.9787234 | S4: mean | T4: {=AVERAGE(IF(ISNUMBER(G223:G277),G223:G277))} -> 1.8043478 | U4: mean | V4: {=AVERAGE(IF(ISNUMBER(G278:G332),G278:G332))} -> 1.9347826
A5: 2017 | B5: 1 | C5: Philadelphia 76ers | D5: Markelle Fultz | E5: Washington | F5: 🟥 Bust | G5: {=_xlfn.SWITCH(F5,"🟩 Superstar",5,"🟦 Star / All-Star",4,"🟨 Above-average starter",3,"⬛ Contributor / role player",2,"🟥 Bust",1,"⏳ Too early to tell","")} -> 1 | I5: median | J5: {=MEDIAN(IF(ISNUMBER(G3:G332),G3:G332))} -> 2 | K5: median | L5: {=MEDIAN(IF(ISNUMBER(G3:G57),G3:G57))} -> 4 | M5: median | N5: {=MEDIAN(IF(ISNUMBER(G58:G112),G58:G112))} -> 2 | O5: median | P5: {=MEDIAN(IF(ISNUMBER(G113:G167),G113:G167))} -> 2 | Q5: median | R5: {=MEDIAN(IF(ISNUMBER(G168:G222),G168:G222))} -> 2 | S5: median | T5: {=MEDIAN(IF(ISNUMBER(G223:G277),G223:G277))} -> 1.5 | U5: median | V5: {=MEDIAN(IF(ISNUMBER(G278:G332),G278:G332))} -> 2
A6: 2018 | B6: 1 | C6: Phoenix Suns | D6: Deandre Ayton | E6: Arizona | F6: 🟨 Above-average starter | G6: {=_xlfn.SWITCH(F6,"🟩 Superstar",5,"🟦 Star / All-Star",4,"🟨 Above-average starter",3,"⬛ Contributor / role player",2,"🟥 Bust",1,"⏳ Too early to tell","")} -> 3 | I6: std dev | J6: {=_xlfn.STDEV.S(IF(ISNUMBER(G3:G332),G3:G332))} -> 1.1823242 | K6: std dev | L6: {=_xlfn.STDEV.S(IF(ISNUMBER(G3:G57),G3:G57))} -> 1.2995726 | M6: std dev | N6: {=_xlfn.STDEV.S(IF(ISNUMBER(G58:G112),G58:G112))} -> 0.99086739 | O6: std dev | P6: {=_xlfn.STDEV.S(IF(ISNUMBER(G113:G167),G113:G167))} -> 1.2843267 | Q6: std dev | R6: {=_xlfn.STDEV.S(IF(ISNUMBER(G168:G222),G168:G222))} -> 0.92052352 | S6: std dev | T6: {=_xlfn.STDEV.S(IF(ISNUMBER(G223:G277),G223:G277))} -> 1.0026535 | U6: std dev | V6: {=_xlfn.STDEV.S(IF(ISNUMBER(G278:G332),G278:G332))} -> 0.99782372
A7: 2019 | B7: 1 | C7: New Orleans Pelicans | D7: Zion Williamson | E7: Duke | F7: 🟦 Star / All-Star | G7: {=_xlfn.SWITCH(F7,"🟩 Superstar",5,"🟦 Star / All-Star",4,"🟨 Above-average starter",3,"⬛ Contributor / role player",2,"🟥 Bust",1,"⏳ Too early to tell","")} -> 4 | I7: r | J7: =CORREL(B3:B332,G3:G332) -> -0.3509985 | K7: r | L7: =CORREL(B3:B57,G3:G57) -> -0.28124169 | M7: r | N7: =CORREL(B58:B112,G58:G112) -> -0.19245009 | O7: r | P7: =CORREL(B113:B167,G113:G167) -> -0.28458024 | Q7: r | R7: =CORREL(B168:B222,G168:G222) -> 0.01539988 | S7: r | T7: =CORREL(B223:B277,G223:G277) -> -0.16275784 | U7: r | V7: =CORREL(B278:B332,G278:G332) -> 0.16756725
A8: 2020 | B8: 1 | C8: Minnesota Timberwolves | D8: Anthony Edwards | E8: Georgia | F8: 🟩 Superstar | G8: {=_xlfn.SWITCH(F8,"🟩 Superstar",5,"🟦 Star / All-Star",4,"🟨 Above-average starter",3,"⬛ Contributor / role player",2,"🟥 Bust",1,"⏳ Too early to tell","")} -> 5 | I8: r^2 | J8: =J7*J7 -> 0.12319994 | K8: r^2 | L8: =L7*L7 -> 0.07909689 | M8: r^2 | N8: =N7*N7 -> 0.037037037 | O8: r^2 | P8: =P7*P7 -> 0.080985915 | Q8: r^2 | R8: =R7*R7 -> 0.00023715632 | S8: r^2 | T8: =T7*T7 -> 0.026490113 | U8: r^2 | V8: =V7*V7 -> 0.028078782
A9: 2021 | B9: 1 | C9: Detroit Pistons | D9: Cade Cunningham | E9: Oklahoma State | F9: 🟩 Superstar | G9: {=_xlfn.SWITCH(F9,"🟩 Superstar",5,"🟦 Star / All-Star",4,"🟨 Above-average starter",3,"⬛ Contributor / role player",2,"🟥 Bust",1,"⏳ Too early to tell","")} -> 5
A10: 2022 | B10: 1 | C10: Orlando Magic | D10: Paolo Banchero | E10: Duke | F10: 🟦 Star / All-Star | G10: {=_xlfn.SWITCH(F10,"🟩 Superstar",5,"🟦 Star / All-Star",4,"🟨 Above-average starter",3,"⬛ Contributor / role player",2,"🟥 Bust",1,"⏳ Too early to tell","")} -> 4
A11: 2023 | B11: 1 | C11: San Antonio Spurs | D11: Victor Wembanyama | E11: France | F11: 🟩 Superstar | G11: {=_xlfn.SWITCH(F11,"🟩 Superstar",5,"🟦 Star / All-Star",4,"🟨 Above-average starter",3,"⬛ Contributor / role player",2,"🟥 Bust",1,"⏳ Too early to tell","")} -> 5 | J11: n | K11: mean | L11: median | M11: std dev | N11: mode
A12: 2024 | B12: 1 | C12: Atlanta Hawks | D12: Zaccharie Risacher | E12: France | F12: ⏳ Too early to tell | G12: {=_xlfn.SWITCH(F12,"🟩 Superstar",5,"🟦 Star / All-Star",4,"🟨 Above-average starter",3,"⬛ Contributor / role player",2,"🟥 Bust",1,"⏳ Too early to tell","")} | I12: Pick 1 | J12: =COUNT(G3:G13) -> 9 | K12: {=AVERAGE(IF(ISNUMBER(G3:G13),G3:G13))} -> 4 | L12: {=MEDIAN(IF(ISNUMBER(G3:G13),G3:G13))} -> 4 | M12: {=_xlfn.STDEV.S(IF(ISNUMBER(G3:G13),G3:G13))} -> 1.3228757 | N12: {=MODE(IF(ISNUMBER(G3:G13),G3:G13))} -> 5
A13: 2025 | B13: 1 | C13: Dallas Mavericks | D13: Cooper Flagg | E13: Duke | F13: ⏳ Too early to tell | G13: {=_xlfn.SWITCH(F13,"🟩 Superstar",5,"🟦 Star / All-Star",4,"🟨 Above-average starter",3,"⬛ Contributor / role player",2,"🟥 Bust",1,"⏳ Too early to tell","")} | I13: Pick 2 | J13: =COUNT(G14:G24) -> 9 | K13: {=AVERAGE(IF(ISNUMBER(G14:G24),G14:G24))} -> 3 | L13: {=MEDIAN(IF(ISNUMBER(G14:G24),G14:G24))} -> 3 | M13: {=_xlfn.STDEV.S(IF(ISNUMBER(G14:G24),G14:G24))} -> 1.2247449 | N13: {=MODE(IF(ISNUMBER(G14:G24),G14:G24))} -> 4
A14: 2015 | B14: 2 | C14: LA Lakers | D14: D'Angelo Russell | E14: Ohio State | F14: 🟦 Star / All-Star | G14: {=_xlfn.SWITCH(F14,"🟩 Superstar",5,"🟦 Star / All-Star",4,"🟨 Above-average starter",3,"⬛ Contributor / role player",2,"🟥 Bust",1,"⏳ Too early to tell","")} -> 4 | I14: Pick 3 | J14: =COUNT(G25:G35) -> 9 | K14: {=AVERAGE(IF(ISNUMBER(G25:G35),G25:G35))} -> 3.5555556 | L14: {=MEDIAN(IF(ISNUMBER(G25:G35),G25:G35))} -> 4 | M14: {=_xlfn.STDEV.S(IF(ISNUMBER(G25:G35),G25:G35))} -> 1.4240006 | N14: {=MODE(IF(ISNUMBER(G25:G35),G25:G35))} -> 5
A15: 2016 | B15: 2 | C15: LA Lakers | D15: Brandon Ingram | E15: Duke | F15: 🟦 Star / All-Star | G15: {=_xlfn.SWITCH(F15,"🟩 Superstar",5,"🟦 Star / All-Star",4,"🟨 Above-average starter",3,"⬛ Contributor / role player",2,"🟥 Bust",1,"⏳ Too early to tell","")} -> 4 | I15: Pick 4 | J15: =COUNT(G36:G46) -> 9 | K15: {=AVERAGE(IF(ISNUMBER(G36:G46),G36:G46))} -> 2.8888889 | L15: {=MEDIAN(IF(ISNUMBER(G36:G46),G36:G46))} -> 3 | M15: {=_xlfn.STDEV.S(IF(ISNUMBER(G36:G46),G36:G46))} -> 1.2692955 | N15: {=MODE(IF(ISNUMBER(G36:G46),G36:G46))} -> 4
A16: 2017 | B16: 2 | C16: LA Lakers | D16: Lonzo Ball | E16: UCLA | F16: 🟨 Above-average starter | G16: {=_xlfn.SWITCH(F16,"🟩 Superstar",5,"🟦 Star / All-Star",4,"🟨 Above-average starter",3,"⬛ Contributor / role player",2,"🟥 Bust",1,"⏳ Too early to tell","")} -> 3 | I16: Pick 5 | J16: =COUNT(G47:G57) -> 9 | K16: {=AVERAGE(IF(ISNUMBER(G47:G57),G47:G57))} -> 2.7777778 | L16: {=MEDIAN(IF(ISNUMBER(G47:G57),G47:G57))} -> 3 | M16: {=_xlfn.STDEV.S(IF(ISNUMBER(G47:G57),G47:G57))} -> 1.0929064 | N16: {=MODE(IF(ISNUMBER(G47:G57),G47:G57))} -> 2
A17: 2018 | B17: 2 | C17: Sacramento Kings | D17: Marvin Bagley III | E17: Duke | F17: 🟥 Bust | G17: {=_xlfn.SWITCH(F17,"🟩 Superstar",5,"🟦 Star / All-Star",4,"🟨 Above-average starter",3,"⬛ Contributor / role player",2,"🟥 Bust",1,"⏳ Too early to tell","")} -> 1 | I17: Pick 6 | J17: =COUNT(G58:G68) -> 9 | K17: {=AVERAGE(IF(ISNUMBER(G58:G68),G58:G68))} -> 2.3333333 | L17: {=MEDIAN(IF(ISNUMBER(G58:G68),G58:G68))} -> 3 | M17: {=_xlfn.STDEV.S(IF(ISNUMBER(G58:G68),G58:G68))} -> 0.8660254 | N17: {=MODE(IF(ISNUMBER(G58:G68),G58:G68))} -> 3
A18: 2019 | B18: 2 | C18: Memphis Grizzlies | D18: Ja Morant | E18: Murray State | F18: 🟦 Star / All-Star | G18: {=_xlfn.SWITCH(F18,"🟩 Superstar",5,"🟦 Star / All-Star",4,"🟨 Above-average starter",3,"⬛ Contributor / role player",2,"🟥 Bust",1,"⏳ Too early to tell","")} -> 4 | I18: Pick 7 | J18: =COUNT(G69:G79) -> 9 | K18: {=AVERAGE(IF(ISNUMBER(G69:G79),G69:G79))} -> 2.5555556 | L18: {=MEDIAN(IF(ISNUMBER(G69:G79),G69:G79))} -> 3 | M18: {=_xlfn.STDEV.S(IF(ISNUMBER(G69:G79),G69:G79))} -> 1.1303883 | N18: {=MODE(IF(ISNUMBER(G69:G79),G69:G79))} -> 3
A19: 2020 | B19: 2 | C19: Golden State Warriors | D19: James Wiseman | E19: Memphis | F19: 🟥 Bust | G19: {=_xlfn.SWITCH(F19,"🟩 Superstar",5,"🟦 Star / All-Star",4,"🟨 Above-average starter",3,"⬛ Contributor / role player",2,"🟥 Bust",1,"⏳ Too early to tell","")} -> 1 | I19: Pick 8 | J19: =COUNT(G80:G90) -> 9 | K19: {=AVERAGE(IF(ISNUMBER(G80:G90),G80:G90))} -> 2.1111111 | L19: {=MEDIAN(IF(ISNUMBER(G80:G90),G80:G90))} -> 2 | M19: {=_xlfn.STDEV.S(IF(ISNUMBER(G80:G90),G80:G90))} -> 1.0540926 | N19: {=MODE(IF(ISNUMBER(G80:G90),G80:G90))} -> 1
A20: 2021 | B20: 2 | C20: Houston Rockets | D20: Jalen Green | E20: G League Ignite | F20: 🟨 Above-average starter | G20: {=_xlfn.SWITCH(F20,"🟩 Superstar",5,"🟦 Star / All-Star",4,"🟨 Above-average starter",3,"⬛ Contributor / role player",2,"🟥 Bust",1,"⏳ Too early to tell","")} -> 3 | I20: Pick 9 | J20: =COUNT(G91:G101) -> 9 | K20: {=AVERAGE(IF(ISNUMBER(G91:G101),G91:G101))} -> 2.1111111 | L20: {=MEDIAN(IF(ISNUMBER(G91:G101),G91:G101))} -> 2 | M20: {=_xlfn.STDEV.S(IF(ISNUMBER(G91:G101),G91:G101))} -> 0.92796073 | N20: {=MODE(IF(ISNUMBER(G91:G101),G91:G101))} -> 2
A21: 2022 | B21: 2 | C21: Oklahoma City Thunder | D21: Chet Holmgren | E21: Gonzaga | F21: 🟦 Star / All-Star | G21: {=_xlfn.SWITCH(F21,"🟩 Superstar",5,"🟦 Star / All-Star",4,"🟨 Above-average starter",3,"⬛ Contributor / role player",2,"🟥 Bust",1,"⏳ Too early to tell","")} -> 4 | I21: Pick 10 | J21: =COUNT(G102:G112) -> 9 | K21: {=AVERAGE(IF(ISNUMBER(G102:G112),G102:G112))} -> 1.8888889 | L21: {=MEDIAN(IF(ISNUMBER(G102:G112),G102:G112))} -> 2 | M21: {=_xlfn.STDEV.S(IF(ISNUMBER(G102:G112),G102:G112))} -> 1.0540926 | N21: {=MODE(IF(ISNUMBER(G102:G112),G102:G112))} -> 1
A22: 2023 | B22: 2 | C22: Charlotte Hornets | D22: Brandon Miller | E22: Alabama | F22: 🟨 Above-average starter | G22: {=_xlfn.SWITCH(F22,"🟩 Superstar",5,"🟦 Star / All-Star",4,"🟨 Above-average starter",3,"⬛ Contributor / role player",2,"🟥 Bust",1,"⏳ Too early to tell","")} -> 3 | I22: Pick 11 | J22: =COUNT(G113:G123) -> 9 | K22: {=AVERAGE(IF(ISNUMBER(G113:G123),G113:G123))} -> 2.6666667 | L22: {=MEDIAN(IF(ISNUMBER(G113:G123),G113:G123))} -> 3 | M22: {=_xlfn.STDEV.S(IF(ISNUMBER(G113:G123),G113:G123))} -> 1.3228757 | N22: {=MODE(IF(ISNUMBER(G113:G123),G113:G123))} -> 3
A23: 2024 | B23: 2 | C23: Washington Wizards | D23: Alex Sarr | E23: France | F23: ⏳ Too early to tell | G23: {=_xlfn.SWITCH(F23,"🟩 Superstar",5,"🟦 Star / All-Star",4,"🟨 Above-average starter",3,"⬛ Contributor / role player",2,"🟥 Bust",1,"⏳ Too early to tell","")} | I23: Pick 12 | J23: =COUNT(G124:G134) -> 9 | K23: {=AVERAGE(IF(ISNUMBER(G124:G134),G124:G134))} -> 2.7777778 | L23: {=MEDIAN(IF(ISNUMBER(G124:G134),G124:G134))} -> 3 | M23: {=_xlfn.STDEV.S(IF(ISNUMBER(G124:G134),G124:G134))} -> 1.2018504 | N23: {=MODE(IF(ISNUMBER(G124:G134),G124:G134))} -> 2
A24: 2025 | B24: 2 | C24: San Antonio Spurs | D24: Dylan Harper | E24: Rutgers | F24: ⏳ Too early to tell | G24: {=_xlfn.SWITCH(F24,"🟩 Superstar",5,"🟦 Star / All-Star",4,"🟨 Above-average starter",3,"⬛ Contributor / role player",2,"🟥 Bust",1,"⏳ Too early to tell","")} | I24: Pick 13 | J24: =COUNT(G135:G145) -> 9 | K24: {=AVERAGE(IF(ISNUMBER(G135:G145),G135:G145))} -> 2.6666667 | L24: {=MEDIAN(IF(ISNUMBER(G135:G145),G135:G145))} -> 2 | M24: {=_xlfn.STDEV.S(IF(ISNUMBER(G135:G145),G135:G145))} -> 1.8027756 | N24: {=MODE(IF(ISNUMBER(G135:G145),G135:G145))} -> 1
A25: 2015 | B25: 3 | C25: Philadelphia 76ers | D25: Jahlil Okafor | E25: Duke | F25: 🟥 Bust | G25: {=_xlfn.SWITCH(F25,"🟩 Superstar",5,"🟦 Star / All-Star",4,"🟨 Above-average starter",3,"⬛ Contributor / role player",2,"🟥 Bust",1,"⏳ Too early to tell","")} -> 1 | I25: Pick 14 | J25: =COUNT(G146:G156) -> 9 | K25: {=AVERAGE(IF(ISNUMBER(G146:G156),G146:G156))} -> 2 | L25: {=MEDIAN(IF(ISNUMBER(G146:G156),G146:G156))} -> 2 | M25: {=_xlfn.STDEV.S(IF(ISNUMBER(G146:G156),G146:G156))} -> 1 | N25: {=MODE(IF(ISNUMBER(G146:G156),G146:G156))} -> 2
A26: 2016 | B26: 3 | C26: Boston Celtics | D26: Jaylen Brown | E26: California | F26: 🟩 Superstar | G26: {=_xlfn.SWITCH(F26,"🟩 Superstar",5,"🟦 Star / All-Star",4,"🟨 Above-average starter",3,"⬛ Contributor / role player",2,"🟥 Bust",1,"⏳ Too early to tell","")} -> 5 | I26: Pick 15 | J26: =COUNT(G157:G167) -> 9 | K26: {=AVERAGE(IF(ISNUMBER(G157:G167),G157:G167))} -> 1.7777778 | L26: {=MEDIAN(IF(ISNUMBER(G157:G167),G157:G167))} -> 2 | M26: {=_xlfn.STDEV.S(IF(ISNUMBER(G157:G167),G157:G167))} -> 0.83333333 | N26: {=MODE(IF(ISNUMBER(G157:G167),G157:G167))} -> 1
A27: 2017 | B27: 3 | C27: Boston Celtics | D27: Jayson Tatum | E27: Duke | F27: 🟩 Superstar | G27: {=_xlfn.SWITCH(F27,"🟩 Superstar",5,"🟦 Star / All-Star",4,"🟨 Above-average starter",3,"⬛ Contributor / role player",2,"🟥 Bust",1,"⏳ Too early to tell","")} -> 5 | I27: Pick 16 | J27: =COUNT(G168:G178) -> 10 | K27: {=AVERAGE(IF(ISNUMBER(G168:G178),G168:G178))} -> 2.2 | L27: {=MEDIAN(IF(ISNUMBER(G168:G178),G168:G178))} -> 2 | M27: {=_xlfn.STDEV.S(IF(ISNUMBER(G168:G178),G168:G178))} -> 1.0327956 | N27: {=MODE(IF(ISNUMBER(G168:G178),G168:G178))} -> 3
A28: 2018 | B28: 3 | C28: Atlanta Hawks | D28: Luka Doncic | E28: Slovenia | F28: 🟩 Superstar | G28: {=_xlfn.SWITCH(F28,"🟩 Superstar",5,"🟦 Star / All-Star",4,"🟨 Above-average starter",3,"⬛ Contributor / role player",2,"🟥 Bust",1,"⏳ Too early to tell","")} -> 5 | I28: Pick 17 | J28: =COUNT(G179:G189) -> 10 | K28: {=AVERAGE(IF(ISNUMBER(G179:G189),G179:G189))} -> 1.8 | L28: {=MEDIAN(IF(ISNUMBER(G179:G189),G179:G189))} -> 1 | M28: {=_xlfn.STDEV.S(IF(ISNUMBER(G179:G189),G179:G189))} -> 1.1352924 | N28: {=MODE(IF(ISNUMBER(G179:G189),G179:G189))} -> 1
A29: 2019 | B29: 3 | C29: New York Knicks | D29: RJ Barrett | E29: Duke | F29: 🟨 Above-average starter | G29: {=_xlfn.SWITCH(F29,"🟩 Superstar",5,"🟦 Star / All-Star",4,"🟨 Above-average starter",3,"⬛ Contributor / role player",2,"🟥 Bust",1,"⏳ Too early to tell","")} -> 3 | I29: Pick 18 | J29: =COUNT(G190:G200) -> 9 | K29: {=AVERAGE(IF(ISNUMBER(G190:G200),G190:G200))} -> 1.6666667 | L29: {=MEDIAN(IF(ISNUMBER(G190:G200),G190:G200))} -> 2 | M29: {=_xlfn.STDEV.S(IF(ISNUMBER(G190:G200),G190:G200))} -> 0.5 | N29: {=MODE(IF(ISNUMBER(G190:G200),G190:G200))} -> 2
A30: 2020 | B30: 3 | C30: Charlotte Hornets | D30: LaMelo Ball | E30: (none) Australia/prep | F30: 🟦 Star / All-Star | G30: {=_xlfn.SWITCH(F30,"🟩 Superstar",5,"🟦 Star / All-Star",4,"🟨 Above-average starter",3,"⬛ Contributor / role player",2,"🟥 Bust",1,"⏳ Too early to tell","")} -> 4 | I30: Pick 19 | J30: =COUNT(G201:G211) -> 9 | K30: {=AVERAGE(IF(ISNUMBER(G201:G211),G201:G211))} -> 2.1111111 | L30: {=MEDIAN(IF(ISNUMBER(G201:G211),G201:G211))} -> 2 | M30: {=_xlfn.STDEV.S(IF(ISNUMBER(G201:G211),G201:G211))} -> 0.92796073 | N30: {=MODE(IF(ISNUMBER(G201:G211),G201:G211))} -> 3
A31: 2021 | B31: 3 | C31: Cleveland Cavaliers | D31: Evan Mobley | E31: USC | F31: 🟦 Star / All-Star | G31: {=_xlfn.SWITCH(F31,"🟩 Superstar",5,"🟦 Star / All-Star",4,"🟨 Above-average starter",3,"⬛ Contributor / role player",2,"🟥 Bust",1,"⏳ Too early to tell","")} -> 4 | I31: Pick 20 | J31: =COUNT(G212:G222) -> 9 | K31: {=AVERAGE(IF(ISNUMBER(G212:G222),G212:G222))} -> 2.1111111 | L31: {=MEDIAN(IF(ISNUMBER(G212:G222),G212:G222))} -> 2 | M31: {=_xlfn.STDEV.S(IF(ISNUMBER(G212:G222),G212:G222))} -> 0.92796073 | N31: {=MODE(IF(ISNUMBER(G212:G222),G212:G222))} -> 2
A32: 2022 | B32: 3 | C32: Houston Rockets | D32: Jabari Smith Jr. | E32: Auburn | F32: 🟨 Above-average starter | G32: {=_xlfn.SWITCH(F32,"🟩 Superstar",5,"🟦 Star / All-Star",4,"🟨 Above-average starter",3,"⬛ Contributor / role player",2,"🟥 Bust",1,"⏳ Too early to tell","")} -> 3 | I32: Pick 21 | J32: =COUNT(G223:G233) -> 9 | K32: {=AVERAGE(IF(ISNUMBER(G223:G233),G223:G233))} -> 2.1111111 | L32: {=MEDIAN(IF(ISNUMBER(G223:G233),G223:G233))} -> 2 | M32: {=_xlfn.STDEV.S(IF(ISNUMBER(G223:G233),G223:G233))} -> 1.2692955 | N32: {=MODE(IF(ISNUMBER(G223:G233),G223:G233))} -> 2
A33: 2023 | B33: 3 | C33: Portland Trail Blazers | D33: Scoot Henderson | E33: G League Ignite | F33: ⬛ Contributor / role player | G33: {=_xlfn.SWITCH(F33,"🟩 Superstar",5,"🟦 Star / All-Star",4,"🟨 Above-average starter",3,"⬛ Contributor / role player",2,"🟥 Bust",1,"⏳ Too early to tell","")} -> 2 | I33: Pick 22 | J33: =COUNT(G234:G244) -> 9 | K33: {=AVERAGE(IF(ISNUMBER(G234:G244),G234:G244))} -> 2 | L33: {=MEDIAN(IF(ISNUMBER(G234:G244),G234:G244))} -> 2 | M33: {=_xlfn.STDEV.S(IF(ISNUMBER(G234:G244),G234:G244))} -> 1.118034 | N33: {=MODE(IF(ISNUMBER(G234:G244),G234:G244))} -> 1
A34: 2024 | B34: 3 | C34: Houston Rockets | D34: Reed Sheppard | E34: Kentucky | F34: ⏳ Too early to tell | G34: {=_xlfn.SWITCH(F34,"🟩 Superstar",5,"🟦 Star / All-Star",4,"🟨 Above-average starter",3,"⬛ Contributor / role player",2,"🟥 Bust",1,"⏳ Too early to tell","")} | I34: Pick 23 | J34: =COUNT(G245:G255) -> 9 | K34: {=AVERAGE(IF(ISNUMBER(G245:G255),G245:G255))} -> 1.5555556 | L34: {=MEDIAN(IF(ISNUMBER(G245:G255),G245:G255))} -> 1 | M34: {=_xlfn.STDEV.S(IF(ISNUMBER(G245:G255),G245:G255))} -> 1.0137938 | N34: {=MODE(IF(ISNUMBER(G245:G255),G245:G255))} -> 1
A35: 2025 | B35: 3 | C35: Philadelphia 76ers | D35: VJ Edgecombe | E35: Baylor | F35: ⏳ Too early to tell | G35: {=_xlfn.SWITCH(F35,"🟩 Superstar",5,"🟦 Star / All-Star",4,"🟨 Above-average starter",3,"⬛ Contributor / role player",2,"🟥 Bust",1,"⏳ Too early to tell","")} | I35: Pick 24 | J35: =COUNT(G256:G266) -> 9 | K35: {=AVERAGE(IF(ISNUMBER(G256:G266),G256:G266))} -> 1.6666667 | L35: {=MEDIAN(IF(ISNUMBER(G256:G266),G256:G266))} -> 1 | M35: {=_xlfn.STDEV.S(IF(ISNUMBER(G256:G266),G256:G266))} -> 0.8660254 | N35: {=MODE(IF(ISNUMBER(G256:G266),G256:G266))} -> 1
A36: 2015 | B36: 4 | C36: New York Knicks | D36: Kristaps Porzingis | E36: Latvia | F36: 🟦 Star / All-Star | G36: {=_xlfn.SWITCH(F36,"🟩 Superstar",5,"🟦 Star / All-Star",4,"🟨 Above-average starter",3,"⬛ Contributor / role player",2,"🟥 Bust",1,"⏳ Too early to tell","")} -> 4 | I36: Pick 25 | J36: =COUNT(G267:G277) -> 10 | K36: {=AVERAGE(IF(ISNUMBER(G267:G277),G267:G277))} -> 1.7 | L36: {=MEDIAN(IF(ISNUMBER(G267:G277),G267:G277))} -> 1.5 | M36: {=_xlfn.STDEV.S(IF(ISNUMBER(G267:G277),G267:G277))} -> 0.8232726 | N36: {=MODE(IF(ISNUMBER(G267:G277),G267:G277))} -> 1
A37: 2016 | B37: 4 | C37: Phoenix Suns | D37: Dragan Bender | E37: Croatia | F37: 🟥 Bust | G37: {=_xlfn.SWITCH(F37,"🟩 Superstar",5,"🟦 Star / All-Star",4,"🟨 Above-average starter",3,"⬛ Contributor / role player",2,"🟥 Bust",1,"⏳ Too early to tell","")} -> 1 | I37: Pick 26 | J37: =COUNT(G278:G288) -> 10 | K37: {=AVERAGE(IF(ISNUMBER(G278:G288),G278:G288))} -> 1.6 | L37: {=MEDIAN(IF(ISNUMBER(G278:G288),G278:G288))} -> 1.5 | M37: {=_xlfn.STDEV.S(IF(ISNUMBER(G278:G288),G278:G288))} -> 0.6992059 | N37: {=MODE(IF(ISNUMBER(G278:G288),G278:G288))} -> 1
A38: 2017 | B38: 4 | C38: Phoenix Suns | D38: Josh Jackson | E38: Kansas | F38: 🟥 Bust | G38: {=_xlfn.SWITCH(F38,"🟩 Superstar",5,"🟦 Star / All-Star",4,"🟨 Above-average starter",3,"⬛ Contributor / role player",2,"🟥 Bust",1,"⏳ Too early to tell","")} -> 1 | I38: Pick 27 | J38: =COUNT(G289:G299) -> 9 | K38: {=AVERAGE(IF(ISNUMBER(G289:G299),G289:G299))} -> 2.2222222 | L38: {=MEDIAN(IF(ISNUMBER(G289:G299),G289:G299))} -> 2 | M38: {=_xlfn.STDEV.S(IF(ISNUMBER(G289:G299),G289:G299))} -> 1.0929064 | N38: {=MODE(IF(ISNUMBER(G289:G299),G289:G299))} -> 3
A39: 2018 | B39: 4 | C39: Memphis Grizzlies | D39: Jaren Jackson Jr. | E39: Michigan State | F39: 🟦 Star / All-Star | G39: {=_xlfn.SWITCH(F39,"🟩 Superstar",5,"🟦 Star / All-Star",4,"🟨 Above-average starter",3,"⬛ Contributor / role player",2,"🟥 Bust",1,"⏳ Too early to tell","")} -> 4 | I39: Pick 28 | J39: =COUNT(G300:G310) -> 9 | K39: {=AVERAGE(IF(ISNUMBER(G300:G310),G300:G310))} -> 1.5555556 | L39: {=MEDIAN(IF(ISNUMBER(G300:G310),G300:G310))} -> 1 | M39: {=_xlfn.STDEV.S(IF(ISNUMBER(G300:G310),G300:G310))} -> 0.8819171 | N39: {=MODE(IF(ISNUMBER(G300:G310),G300:G310))} -> 1
A40: 2019 | B40: 4 | C40: LA Lakers | D40: De'Andre Hunter | E40: Virginia | F40: 🟨 Above-average starter | G40: {=_xlfn.SWITCH(F40,"🟩 Superstar",5,"🟦 Star / All-Star",4,"🟨 Above-average starter",3,"⬛ Contributor / role player",2,"🟥 Bust",1,"⏳ Too early to tell","")} -> 3 | I40: Pick 29 | J40: =COUNT(G311:G321) -> 9 | K40: {=AVERAGE(IF(ISNUMBER(G311:G321),G311:G321))} -> 2.1111111 | L40: {=MEDIAN(IF(ISNUMBER(G311:G321),G311:G321))} -> 2 | M40: {=_xlfn.STDEV.S(IF(ISNUMBER(G311:G321),G311:G321))} -> 1.2692955 | N40: {=MODE(IF(ISNUMBER(G311:G321),G311:G321))} -> 1
...

Sheet Charts
B1: mean | C1: r^2 | D1: superstar % | E1: star/all-star % | F1: all star + % | K1: mean | L1: mode
A2: Picks 1-5 | B2: ='Stat Analysis'!L4 -> 3.2444444 | C2: ='Stat Analysis'!L8*100 -> 7.909689 | D2: =COUNTIF('Stat Analysis'!G3:G57,">4")/45 -> 0.15555556 | E2: =COUNTIFS('Stat Analysis'!G3:G57,">3",'Stat Analysis'!G3:G57,"<5")/45 -> 0.35555556 | F2: =COUNTIF('Stat Analysis'!G3:G57,">3")/45 -> 0.51111111 | J2: Pick 1 | K2: ='Stat Analysis'!K12 -> 4 | L2: ='Stat Analysis'!N12 -> 5
A3: Picks 6-10 | B3: ='Stat Analysis'!N4 -> 2.2 | C3: ='Stat Analysis'!N8*100 -> 3.7037037 | D3: =COUNTIF('Stat Analysis'!G58:G112,">4")/45 -> 0 | E3: =COUNTIFS('Stat Analysis'!G58:G112,">3",'Stat Analysis'!G58:G112,"<5")/45 -> 0.11111111 | F3: =COUNTIF('Stat Analysis'!G58:G112,">3")/45 -> 0.11111111 | J3: Pick 2 | K3: ='Stat Analysis'!K13 -> 3 | L3: ='Stat Analysis'!N13 -> 4
A4: Picks 11-15 | B4: ='Stat Analysis'!P4 -> 2.3777778 | C4: ='Stat Analysis'!P8*100 -> 8.0985915 | D4: =COUNTIF('Stat Analysis'!G113:G167,">4")/45 -> 0.088888889 | E4: =COUNTIFS('Stat Analysis'!G113:G167,">3",'Stat Analysis'!G113:G167,"<5")/45 -> 0.11111111 | F4: =COUNTIF('Stat Analysis'!G113:G167,">3")/45 -> 0.2 | J4: Pick 3 | K4: ='Stat Analysis'!K14 -> 3.5555556 | L4: ='Stat Analysis'!N14 -> 5
A5: Picks 16-20 | B5: ='Stat Analysis'!R4 -> 1.9787234 | C5: ='Stat Analysis'!R8*100 -> 0.023715632 | D5: =COUNTIF('Stat Analysis'!G168:G222,">4")/47 -> 0 | E5: =COUNTIFS('Stat Analysis'!G168:G222,">3",'Stat Analysis'!G168:G222,"<5")/47 -> 0.063829787 | F5: =COUNTIF('Stat Analysis'!G168:G222,">3")/47 -> 0.063829787 | J5: Pick 4 | K5: ='Stat Analysis'!K15 -> 2.8888889 | L5: ='Stat Analysis'!N15 -> 4
A6: Picks 21-25 | B6: ='Stat Analysis'!T4 -> 1.8043478 | C6: ='Stat Analysis'!T8*100 -> 2.6490113 | D6: =COUNTIF('Stat Analysis'!G223:G277,">4")/46 -> 0.02173913 | E6: =COUNTIFS('Stat Analysis'!G223:G277,">3",'Stat Analysis'!G223:G277,"<5")/46 -> 0.043478261 | F6: =COUNTIF('Stat Analysis'!G223:G277,">3")/46 -> 0.065217391 | J6: Pick 5 | K6: ='Stat Analysis'!K16 -> 2.7777778 | L6: ='Stat Analysis'!N16 -> 2
A7: Picks 26-30 | B7: ='Stat Analysis'!V4 -> 1.9347826 | C7: ='Stat Analysis'!V8*100 -> 2.8078782 | D7: =COUNTIF('Stat Analysis'!G278:G332,">4")/46 -> 0 | E7: =COUNTIFS('Stat Analysis'!G278:G332,">3",'Stat Analysis'!G278:G332,"<5")/46 -> 0.086956522 | F7: =COUNTIF('Stat Analysis'!G278:G332,">3")/46 -> 0.086956522 | J7: Pick 6 | K7: ='Stat Analysis'!K17 -> 2.3333333 | L7: ='Stat Analysis'!N17 -> 3
J8: Pick 7 | K8: ='Stat Analysis'!K18 -> 2.5555556 | L8: ='Stat Analysis'!N18 -> 3
J9: Pick 8 | K9: ='Stat Analysis'!K19 -> 2.1111111 | L9: ='Stat Analysis'!N19 -> 1
J10: Pick 9 | K10: ='Stat Analysis'!K20 -> 2.1111111 | L10: ='Stat Analysis'!N20 -> 2
J11: Pick 10 | K11: ='Stat Analysis'!K21 -> 1.8888889 | L11: ='Stat Analysis'!N21 -> 1
J12: Pick 11 | K12: ='Stat Analysis'!K22 -> 2.6666667 | L12: ='Stat Analysis'!N22 -> 3
J13: Pick 12 | K13: ='Stat Analysis'!K23 -> 2.7777778 | L13: ='Stat Analysis'!N23 -> 2
J14: Pick 13 | K14: ='Stat Analysis'!K24 -> 2.6666667 | L14: ='Stat Analysis'!N24 -> 1
J15: Pick 14 | K15: ='Stat Analysis'!K25 -> 2 | L15: ='Stat Analysis'!N25 -> 2
J16: Pick 15 | K16: ='Stat Analysis'!K26 -> 1.7777778 | L16: ='Stat Analysis'!N26 -> 1
J17: Pick 16 | K17: ='Stat Analysis'!K27 -> 2.2 | L17: ='Stat Analysis'!N27 -> 3
J18: Pick 17 | K18: ='Stat Analysis'!K28 -> 1.8 | L18: ='Stat Analysis'!N28 -> 1
J19: Pick 18 | K19: ='Stat Analysis'!K29 -> 1.6666667 | L19: ='Stat Analysis'!N29 -> 2
... J31: Pick 30 | K31: ='Stat Analysis'!K41 -> 2.2222222 | L31: ='Stat Analysis'!N41 -> 2
J33: Career Outcome | K33: Chance
J34: ='Stat Analysis'!F3 -> 🟩 Superstar | K34: =COUNTIF('Stat Analysis'!F3:F332,'Stat Analysis'!F3)/271 -> 0.044280443
J35: ='Stat Analysis'!F4 -> 🟦 Star / All-Star | K35: =COUNTIF('Stat Analysis'!F3:F332,'Stat Analysis'!F4)/271 -> 0.12915129
J36: ='Stat Analysis'!F6 -> 🟨 Above-average starter | K36: =COUNTIF('Stat Analysis'!F5:F334,'Stat Analysis'!F6)/271 -> 0.2103321
J37: ='Stat Analysis'!F33 -> ⬛ Contributor / role player | K37: =COUNTIF('Stat Analysis'!F3:F332,'Stat Analysis'!F33)/271 -> 0.2804428
J38: ='Stat Analysis'!F5 -> 🟥 Bust | K38: =COUNTIF('Stat Analysis'!F3:F332,'Stat Analysis'!F5)/271 -> 0.34686347
